INFO 2023-09-29 20:32:16,232 autoreload 9176 11644 Watching for file changes with StatReloader
WARNING 2023-09-29 20:32:18,082 log 9176 10788 Not Found: /
WARNING 2023-09-29 20:32:18,083 basehttp 9176 10788 "GET / HTTP/1.1" 404 2171
WARNING 2023-09-29 20:32:18,152 log 9176 10788 Not Found: /favicon.ico
WARNING 2023-09-29 20:32:18,152 basehttp 9176 10788 "GET /favicon.ico HTTP/1.1" 404 2222
INFO 2023-09-29 20:35:23,707 autoreload 8528 13148 Watching for file changes with StatReloader
WARNING 2023-09-29 20:35:24,999 log 8528 14772 Not Found: /
WARNING 2023-09-29 20:35:24,999 basehttp 8528 14772 "GET / HTTP/1.1" 404 2171
INFO 2023-09-29 20:35:41,605 basehttp 8528 14772 "GET /admin/ HTTP/1.1" 302 0
INFO 2023-09-29 20:35:41,635 basehttp 8528 14772 "GET /admin/login/?next=/admin/ HTTP/1.1" 200 4181
INFO 2023-09-29 20:35:41,749 basehttp 8528 14772 "GET /static/admin/css/base.css HTTP/1.1" 200 21207
INFO 2023-09-29 20:35:41,752 basehttp 8528 14772 "GET /static/admin/js/nav_sidebar.js HTTP/1.1" 200 3063
INFO 2023-09-29 20:35:41,754 basehttp 8528 13232 "GET /static/admin/css/dark_mode.css HTTP/1.1" 200 2929
INFO 2023-09-29 20:35:41,771 basehttp 8528 11024 "GET /static/admin/js/theme.js HTTP/1.1" 200 1943
INFO 2023-09-29 20:35:41,772 basehttp 8528 14152 "GET /static/admin/css/responsive.css HTTP/1.1" 200 18533
INFO 2023-09-29 20:35:41,775 basehttp 8528 3580 "GET /static/admin/css/login.css HTTP/1.1" 200 958
INFO 2023-09-29 20:35:41,775 basehttp 8528 10448 "GET /static/admin/css/nav_sidebar.css HTTP/1.1" 200 2694
WARNING 2023-09-29 20:35:55,626 log 8528 3580 Not Found: /
WARNING 2023-09-29 20:35:55,627 basehttp 8528 3580 "GET / HTTP/1.1" 404 2171
WARNING 2023-09-29 20:36:24,179 log 8528 3580 Not Found: /
WARNING 2023-09-29 20:36:24,180 basehttp 8528 3580 "GET / HTTP/1.1" 404 2171
ERROR 2023-09-29 20:36:31,090 log 8528 3580 Internal Server Error: /dz_sem3app/
Traceback (most recent call last):
  File "C:\Users\nikol\AppData\Local\Programs\Python\Python311\Lib\site-packages\django\template\backends\django.py", line 61, in render
    return self.template.render(context)
           ^^^^^^^^^^^^^^^^^^^^^^^^^^^^^
  File "C:\Users\nikol\AppData\Local\Programs\Python\Python311\Lib\site-packages\django\template\base.py", line 175, in render
    return self._render(context)
           ^^^^^^^^^^^^^^^^^^^^^
  File "C:\Users\nikol\AppData\Local\Programs\Python\Python311\Lib\site-packages\django\template\base.py", line 167, in _render
    return self.nodelist.render(context)
           ^^^^^^^^^^^^^^^^^^^^^^^^^^^^^
  File "C:\Users\nikol\AppData\Local\Programs\Python\Python311\Lib\site-packages\django\template\base.py", line 1005, in render
    return SafeString("".join([node.render_annotated(context) for node in self]))
                              ^^^^^^^^^^^^^^^^^^^^^^^^^^^^^^^^^^^^^^^^^^^^^^^^^
  File "C:\Users\nikol\AppData\Local\Programs\Python\Python311\Lib\site-packages\django\template\base.py", line 1005, in <listcomp>
    return SafeString("".join([node.render_annotated(context) for node in self]))
                               ^^^^^^^^^^^^^^^^^^^^^^^^^^^^^^
  File "C:\Users\nikol\AppData\Local\Programs\Python\Python311\Lib\site-packages\django\template\base.py", line 966, in render_annotated
    return self.render(context)
           ^^^^^^^^^^^^^^^^^^^^
  File "C:\Users\nikol\AppData\Local\Programs\Python\Python311\Lib\site-packages\django\template\loader_tags.py", line 132, in render
    compiled_parent = self.get_parent(context)
                      ^^^^^^^^^^^^^^^^^^^^^^^^
  File "C:\Users\nikol\AppData\Local\Programs\Python\Python311\Lib\site-packages\django\template\loader_tags.py", line 129, in get_parent
    return self.find_template(parent, context)
           ^^^^^^^^^^^^^^^^^^^^^^^^^^^^^^^^^^^
  File "C:\Users\nikol\AppData\Local\Programs\Python\Python311\Lib\site-packages\django\template\loader_tags.py", line 107, in find_template
    template, origin = context.template.engine.find_template(
                       ^^^^^^^^^^^^^^^^^^^^^^^^^^^^^^^^^^^^^^
  File "C:\Users\nikol\AppData\Local\Programs\Python\Python311\Lib\site-packages\django\template\engine.py", line 161, in find_template
    raise TemplateDoesNotExist(name, tried=tried)
django.template.exceptions.TemplateDoesNotExist: base.html

The above exception was the direct cause of the following exception:

Traceback (most recent call last):
  File "C:\Users\nikol\AppData\Local\Programs\Python\Python311\Lib\site-packages\django\core\handlers\exception.py", line 55, in inner
    response = get_response(request)
               ^^^^^^^^^^^^^^^^^^^^^
  File "C:\Users\nikol\AppData\Local\Programs\Python\Python311\Lib\site-packages\django\core\handlers\base.py", line 197, in _get_response
    response = wrapped_callback(request, *callback_args, **callback_kwargs)
               ^^^^^^^^^^^^^^^^^^^^^^^^^^^^^^^^^^^^^^^^^^^^^^^^^^^^^^^^^^^^
  File "C:\Users\nikol\PycharmProjects\pythonProject2\Django_dz\dz_sem3\dz_sem3app\views.py", line 19, in index
    return render(request, 'dz_sem3app/index.html', context)
           ^^^^^^^^^^^^^^^^^^^^^^^^^^^^^^^^^^^^^^^^^^^^^^^^^
  File "C:\Users\nikol\AppData\Local\Programs\Python\Python311\Lib\site-packages\django\shortcuts.py", line 24, in render
    content = loader.render_to_string(template_name, context, request, using=using)
              ^^^^^^^^^^^^^^^^^^^^^^^^^^^^^^^^^^^^^^^^^^^^^^^^^^^^^^^^^^^^^^^^^^^^^
  File "C:\Users\nikol\AppData\Local\Programs\Python\Python311\Lib\site-packages\django\template\loader.py", line 62, in render_to_string
    return template.render(context, request)
           ^^^^^^^^^^^^^^^^^^^^^^^^^^^^^^^^^
  File "C:\Users\nikol\AppData\Local\Programs\Python\Python311\Lib\site-packages\django\template\backends\django.py", line 63, in render
    reraise(exc, self.backend)
  File "C:\Users\nikol\AppData\Local\Programs\Python\Python311\Lib\site-packages\django\template\backends\django.py", line 84, in reraise
    raise new from exc
django.template.exceptions.TemplateDoesNotExist: base.html
ERROR 2023-09-29 20:36:31,094 basehttp 8528 3580 "GET /dz_sem3app/ HTTP/1.1" 500 132933
INFO 2023-09-29 20:40:56,774 autoreload 10856 15228 Watching for file changes with StatReloader
WARNING 2023-09-29 20:41:00,203 log 10856 4392 Not Found: /
WARNING 2023-09-29 20:41:00,204 basehttp 10856 4392 "GET / HTTP/1.1" 404 2171
ERROR 2023-09-29 20:41:14,515 log 10856 4392 Internal Server Error: /dz_sem3app/
Traceback (most recent call last):
  File "C:\Users\nikol\AppData\Local\Programs\Python\Python311\Lib\site-packages\django\template\backends\django.py", line 61, in render
    return self.template.render(context)
           ^^^^^^^^^^^^^^^^^^^^^^^^^^^^^
  File "C:\Users\nikol\AppData\Local\Programs\Python\Python311\Lib\site-packages\django\template\base.py", line 175, in render
    return self._render(context)
           ^^^^^^^^^^^^^^^^^^^^^
  File "C:\Users\nikol\AppData\Local\Programs\Python\Python311\Lib\site-packages\django\template\base.py", line 167, in _render
    return self.nodelist.render(context)
           ^^^^^^^^^^^^^^^^^^^^^^^^^^^^^
  File "C:\Users\nikol\AppData\Local\Programs\Python\Python311\Lib\site-packages\django\template\base.py", line 1005, in render
    return SafeString("".join([node.render_annotated(context) for node in self]))
                              ^^^^^^^^^^^^^^^^^^^^^^^^^^^^^^^^^^^^^^^^^^^^^^^^^
  File "C:\Users\nikol\AppData\Local\Programs\Python\Python311\Lib\site-packages\django\template\base.py", line 1005, in <listcomp>
    return SafeString("".join([node.render_annotated(context) for node in self]))
                               ^^^^^^^^^^^^^^^^^^^^^^^^^^^^^^
  File "C:\Users\nikol\AppData\Local\Programs\Python\Python311\Lib\site-packages\django\template\base.py", line 966, in render_annotated
    return self.render(context)
           ^^^^^^^^^^^^^^^^^^^^
  File "C:\Users\nikol\AppData\Local\Programs\Python\Python311\Lib\site-packages\django\template\loader_tags.py", line 132, in render
    compiled_parent = self.get_parent(context)
                      ^^^^^^^^^^^^^^^^^^^^^^^^
  File "C:\Users\nikol\AppData\Local\Programs\Python\Python311\Lib\site-packages\django\template\loader_tags.py", line 129, in get_parent
    return self.find_template(parent, context)
           ^^^^^^^^^^^^^^^^^^^^^^^^^^^^^^^^^^^
  File "C:\Users\nikol\AppData\Local\Programs\Python\Python311\Lib\site-packages\django\template\loader_tags.py", line 107, in find_template
    template, origin = context.template.engine.find_template(
                       ^^^^^^^^^^^^^^^^^^^^^^^^^^^^^^^^^^^^^^
  File "C:\Users\nikol\AppData\Local\Programs\Python\Python311\Lib\site-packages\django\template\engine.py", line 161, in find_template
    raise TemplateDoesNotExist(name, tried=tried)
django.template.exceptions.TemplateDoesNotExist: base.html

The above exception was the direct cause of the following exception:

Traceback (most recent call last):
  File "C:\Users\nikol\AppData\Local\Programs\Python\Python311\Lib\site-packages\django\core\handlers\exception.py", line 55, in inner
    response = get_response(request)
               ^^^^^^^^^^^^^^^^^^^^^
  File "C:\Users\nikol\AppData\Local\Programs\Python\Python311\Lib\site-packages\django\core\handlers\base.py", line 197, in _get_response
    response = wrapped_callback(request, *callback_args, **callback_kwargs)
               ^^^^^^^^^^^^^^^^^^^^^^^^^^^^^^^^^^^^^^^^^^^^^^^^^^^^^^^^^^^^
  File "C:\Users\nikol\PycharmProjects\pythonProject2\Django_dz\dz_sem3\dz_sem3app\views.py", line 19, in index
    return render(request, 'dz_sem3app/index.html', context)
           ^^^^^^^^^^^^^^^^^^^^^^^^^^^^^^^^^^^^^^^^^^^^^^^^^
  File "C:\Users\nikol\AppData\Local\Programs\Python\Python311\Lib\site-packages\django\shortcuts.py", line 24, in render
    content = loader.render_to_string(template_name, context, request, using=using)
              ^^^^^^^^^^^^^^^^^^^^^^^^^^^^^^^^^^^^^^^^^^^^^^^^^^^^^^^^^^^^^^^^^^^^^
  File "C:\Users\nikol\AppData\Local\Programs\Python\Python311\Lib\site-packages\django\template\loader.py", line 62, in render_to_string
    return template.render(context, request)
           ^^^^^^^^^^^^^^^^^^^^^^^^^^^^^^^^^
  File "C:\Users\nikol\AppData\Local\Programs\Python\Python311\Lib\site-packages\django\template\backends\django.py", line 63, in render
    reraise(exc, self.backend)
  File "C:\Users\nikol\AppData\Local\Programs\Python\Python311\Lib\site-packages\django\template\backends\django.py", line 84, in reraise
    raise new from exc
django.template.exceptions.TemplateDoesNotExist: base.html
ERROR 2023-09-29 20:41:14,519 basehttp 10856 4392 "GET /dz_sem3app/ HTTP/1.1" 500 132933
WARNING 2023-09-29 20:44:17,738 log 10856 4392 Not Found: /dz_sem3app/fake_orders
WARNING 2023-09-29 20:44:17,739 basehttp 10856 4392 "GET /dz_sem3app/fake_orders HTTP/1.1" 404 3429
WARNING 2023-09-29 20:44:30,275 log 10856 4392 Not Found: /dz_sem3app/fake_orders/10
WARNING 2023-09-29 20:44:30,276 basehttp 10856 4392 "GET /dz_sem3app/fake_orders/10 HTTP/1.1" 404 3438
WARNING 2023-09-29 20:46:09,489 log 10856 4392 Not Found: /sem3app/fake_orders/10
WARNING 2023-09-29 20:46:09,490 basehttp 10856 4392 "GET /sem3app/fake_orders/10 HTTP/1.1" 404 2255
WARNING 2023-09-29 20:46:16,785 log 10856 4392 Not Found: /sem3app/fake_orders/10
WARNING 2023-09-29 20:46:16,785 basehttp 10856 4392 "GET /sem3app/fake_orders/10 HTTP/1.1" 404 2255
WARNING 2023-09-29 20:46:23,607 log 10856 4392 Not Found: /sem3app
WARNING 2023-09-29 20:46:23,608 basehttp 10856 4392 "GET /sem3app HTTP/1.1" 404 2210
INFO 2023-09-29 20:46:31,793 basehttp 10856 4392 "GET /dz_sem3app HTTP/1.1" 301 0
ERROR 2023-09-29 20:46:31,822 log 10856 4056 Internal Server Error: /dz_sem3app/
Traceback (most recent call last):
  File "C:\Users\nikol\AppData\Local\Programs\Python\Python311\Lib\site-packages\django\template\backends\django.py", line 61, in render
    return self.template.render(context)
           ^^^^^^^^^^^^^^^^^^^^^^^^^^^^^
  File "C:\Users\nikol\AppData\Local\Programs\Python\Python311\Lib\site-packages\django\template\base.py", line 175, in render
    return self._render(context)
           ^^^^^^^^^^^^^^^^^^^^^
  File "C:\Users\nikol\AppData\Local\Programs\Python\Python311\Lib\site-packages\django\template\base.py", line 167, in _render
    return self.nodelist.render(context)
           ^^^^^^^^^^^^^^^^^^^^^^^^^^^^^
  File "C:\Users\nikol\AppData\Local\Programs\Python\Python311\Lib\site-packages\django\template\base.py", line 1005, in render
    return SafeString("".join([node.render_annotated(context) for node in self]))
                              ^^^^^^^^^^^^^^^^^^^^^^^^^^^^^^^^^^^^^^^^^^^^^^^^^
  File "C:\Users\nikol\AppData\Local\Programs\Python\Python311\Lib\site-packages\django\template\base.py", line 1005, in <listcomp>
    return SafeString("".join([node.render_annotated(context) for node in self]))
                               ^^^^^^^^^^^^^^^^^^^^^^^^^^^^^^
  File "C:\Users\nikol\AppData\Local\Programs\Python\Python311\Lib\site-packages\django\template\base.py", line 966, in render_annotated
    return self.render(context)
           ^^^^^^^^^^^^^^^^^^^^
  File "C:\Users\nikol\AppData\Local\Programs\Python\Python311\Lib\site-packages\django\template\loader_tags.py", line 132, in render
    compiled_parent = self.get_parent(context)
                      ^^^^^^^^^^^^^^^^^^^^^^^^
  File "C:\Users\nikol\AppData\Local\Programs\Python\Python311\Lib\site-packages\django\template\loader_tags.py", line 129, in get_parent
    return self.find_template(parent, context)
           ^^^^^^^^^^^^^^^^^^^^^^^^^^^^^^^^^^^
  File "C:\Users\nikol\AppData\Local\Programs\Python\Python311\Lib\site-packages\django\template\loader_tags.py", line 107, in find_template
    template, origin = context.template.engine.find_template(
                       ^^^^^^^^^^^^^^^^^^^^^^^^^^^^^^^^^^^^^^
  File "C:\Users\nikol\AppData\Local\Programs\Python\Python311\Lib\site-packages\django\template\engine.py", line 161, in find_template
    raise TemplateDoesNotExist(name, tried=tried)
django.template.exceptions.TemplateDoesNotExist: base.html

The above exception was the direct cause of the following exception:

Traceback (most recent call last):
  File "C:\Users\nikol\AppData\Local\Programs\Python\Python311\Lib\site-packages\django\core\handlers\exception.py", line 55, in inner
    response = get_response(request)
               ^^^^^^^^^^^^^^^^^^^^^
  File "C:\Users\nikol\AppData\Local\Programs\Python\Python311\Lib\site-packages\django\core\handlers\base.py", line 197, in _get_response
    response = wrapped_callback(request, *callback_args, **callback_kwargs)
               ^^^^^^^^^^^^^^^^^^^^^^^^^^^^^^^^^^^^^^^^^^^^^^^^^^^^^^^^^^^^
  File "C:\Users\nikol\PycharmProjects\pythonProject2\Django_dz\dz_sem3\dz_sem3app\views.py", line 19, in index
    return render(request, 'dz_sem3app/index.html', context)
           ^^^^^^^^^^^^^^^^^^^^^^^^^^^^^^^^^^^^^^^^^^^^^^^^^
  File "C:\Users\nikol\AppData\Local\Programs\Python\Python311\Lib\site-packages\django\shortcuts.py", line 24, in render
    content = loader.render_to_string(template_name, context, request, using=using)
              ^^^^^^^^^^^^^^^^^^^^^^^^^^^^^^^^^^^^^^^^^^^^^^^^^^^^^^^^^^^^^^^^^^^^^
  File "C:\Users\nikol\AppData\Local\Programs\Python\Python311\Lib\site-packages\django\template\loader.py", line 62, in render_to_string
    return template.render(context, request)
           ^^^^^^^^^^^^^^^^^^^^^^^^^^^^^^^^^
  File "C:\Users\nikol\AppData\Local\Programs\Python\Python311\Lib\site-packages\django\template\backends\django.py", line 63, in render
    reraise(exc, self.backend)
  File "C:\Users\nikol\AppData\Local\Programs\Python\Python311\Lib\site-packages\django\template\backends\django.py", line 84, in reraise
    raise new from exc
django.template.exceptions.TemplateDoesNotExist: base.html
ERROR 2023-09-29 20:46:31,825 basehttp 10856 4056 "GET /dz_sem3app/ HTTP/1.1" 500 132933
INFO 2023-09-29 20:47:14,769 basehttp 10856 4056 "GET /dz_sem3app/fake_clients/3 HTTP/1.1" 301 0
ERROR 2023-09-29 20:47:14,807 log 10856 7316 Internal Server Error: /dz_sem3app/fake_clients/3/
Traceback (most recent call last):
  File "C:\Users\nikol\AppData\Local\Programs\Python\Python311\Lib\site-packages\django\template\backends\django.py", line 61, in render
    return self.template.render(context)
           ^^^^^^^^^^^^^^^^^^^^^^^^^^^^^
  File "C:\Users\nikol\AppData\Local\Programs\Python\Python311\Lib\site-packages\django\template\base.py", line 175, in render
    return self._render(context)
           ^^^^^^^^^^^^^^^^^^^^^
  File "C:\Users\nikol\AppData\Local\Programs\Python\Python311\Lib\site-packages\django\template\base.py", line 167, in _render
    return self.nodelist.render(context)
           ^^^^^^^^^^^^^^^^^^^^^^^^^^^^^
  File "C:\Users\nikol\AppData\Local\Programs\Python\Python311\Lib\site-packages\django\template\base.py", line 1005, in render
    return SafeString("".join([node.render_annotated(context) for node in self]))
                              ^^^^^^^^^^^^^^^^^^^^^^^^^^^^^^^^^^^^^^^^^^^^^^^^^
  File "C:\Users\nikol\AppData\Local\Programs\Python\Python311\Lib\site-packages\django\template\base.py", line 1005, in <listcomp>
    return SafeString("".join([node.render_annotated(context) for node in self]))
                               ^^^^^^^^^^^^^^^^^^^^^^^^^^^^^^
  File "C:\Users\nikol\AppData\Local\Programs\Python\Python311\Lib\site-packages\django\template\base.py", line 966, in render_annotated
    return self.render(context)
           ^^^^^^^^^^^^^^^^^^^^
  File "C:\Users\nikol\AppData\Local\Programs\Python\Python311\Lib\site-packages\django\template\loader_tags.py", line 132, in render
    compiled_parent = self.get_parent(context)
                      ^^^^^^^^^^^^^^^^^^^^^^^^
  File "C:\Users\nikol\AppData\Local\Programs\Python\Python311\Lib\site-packages\django\template\loader_tags.py", line 129, in get_parent
    return self.find_template(parent, context)
           ^^^^^^^^^^^^^^^^^^^^^^^^^^^^^^^^^^^
  File "C:\Users\nikol\AppData\Local\Programs\Python\Python311\Lib\site-packages\django\template\loader_tags.py", line 107, in find_template
    template, origin = context.template.engine.find_template(
                       ^^^^^^^^^^^^^^^^^^^^^^^^^^^^^^^^^^^^^^
  File "C:\Users\nikol\AppData\Local\Programs\Python\Python311\Lib\site-packages\django\template\engine.py", line 161, in find_template
    raise TemplateDoesNotExist(name, tried=tried)
django.template.exceptions.TemplateDoesNotExist: base.html

The above exception was the direct cause of the following exception:

Traceback (most recent call last):
  File "C:\Users\nikol\AppData\Local\Programs\Python\Python311\Lib\site-packages\django\core\handlers\exception.py", line 55, in inner
    response = get_response(request)
               ^^^^^^^^^^^^^^^^^^^^^
  File "C:\Users\nikol\AppData\Local\Programs\Python\Python311\Lib\site-packages\django\core\handlers\base.py", line 197, in _get_response
    response = wrapped_callback(request, *callback_args, **callback_kwargs)
               ^^^^^^^^^^^^^^^^^^^^^^^^^^^^^^^^^^^^^^^^^^^^^^^^^^^^^^^^^^^^
  File "C:\Users\nikol\PycharmProjects\pythonProject2\Django_dz\dz_sem3\dz_sem3app\views.py", line 34, in fake_clients
    return render(request, 'dz_sem3app/fake.html', context)
           ^^^^^^^^^^^^^^^^^^^^^^^^^^^^^^^^^^^^^^^^^^^^^^^^
  File "C:\Users\nikol\AppData\Local\Programs\Python\Python311\Lib\site-packages\django\shortcuts.py", line 24, in render
    content = loader.render_to_string(template_name, context, request, using=using)
              ^^^^^^^^^^^^^^^^^^^^^^^^^^^^^^^^^^^^^^^^^^^^^^^^^^^^^^^^^^^^^^^^^^^^^
  File "C:\Users\nikol\AppData\Local\Programs\Python\Python311\Lib\site-packages\django\template\loader.py", line 62, in render_to_string
    return template.render(context, request)
           ^^^^^^^^^^^^^^^^^^^^^^^^^^^^^^^^^
  File "C:\Users\nikol\AppData\Local\Programs\Python\Python311\Lib\site-packages\django\template\backends\django.py", line 63, in render
    reraise(exc, self.backend)
  File "C:\Users\nikol\AppData\Local\Programs\Python\Python311\Lib\site-packages\django\template\backends\django.py", line 84, in reraise
    raise new from exc
django.template.exceptions.TemplateDoesNotExist: base.html
ERROR 2023-09-29 20:47:14,810 basehttp 10856 7316 "GET /dz_sem3app/fake_clients/3/ HTTP/1.1" 500 133598
WARNING 2023-09-29 20:49:30,024 log 10856 7316 Not Found: /dz_sem3app/hello
WARNING 2023-09-29 20:49:30,025 basehttp 10856 7316 "GET /dz_sem3app/hello HTTP/1.1" 404 3411
ERROR 2023-09-29 20:51:53,632 log 10856 7316 Internal Server Error: /dz_sem3app/
Traceback (most recent call last):
  File "C:\Users\nikol\AppData\Local\Programs\Python\Python311\Lib\site-packages\django\template\backends\django.py", line 61, in render
    return self.template.render(context)
           ^^^^^^^^^^^^^^^^^^^^^^^^^^^^^
  File "C:\Users\nikol\AppData\Local\Programs\Python\Python311\Lib\site-packages\django\template\base.py", line 175, in render
    return self._render(context)
           ^^^^^^^^^^^^^^^^^^^^^
  File "C:\Users\nikol\AppData\Local\Programs\Python\Python311\Lib\site-packages\django\template\base.py", line 167, in _render
    return self.nodelist.render(context)
           ^^^^^^^^^^^^^^^^^^^^^^^^^^^^^
  File "C:\Users\nikol\AppData\Local\Programs\Python\Python311\Lib\site-packages\django\template\base.py", line 1005, in render
    return SafeString("".join([node.render_annotated(context) for node in self]))
                              ^^^^^^^^^^^^^^^^^^^^^^^^^^^^^^^^^^^^^^^^^^^^^^^^^
  File "C:\Users\nikol\AppData\Local\Programs\Python\Python311\Lib\site-packages\django\template\base.py", line 1005, in <listcomp>
    return SafeString("".join([node.render_annotated(context) for node in self]))
                               ^^^^^^^^^^^^^^^^^^^^^^^^^^^^^^
  File "C:\Users\nikol\AppData\Local\Programs\Python\Python311\Lib\site-packages\django\template\base.py", line 966, in render_annotated
    return self.render(context)
           ^^^^^^^^^^^^^^^^^^^^
  File "C:\Users\nikol\AppData\Local\Programs\Python\Python311\Lib\site-packages\django\template\loader_tags.py", line 132, in render
    compiled_parent = self.get_parent(context)
                      ^^^^^^^^^^^^^^^^^^^^^^^^
  File "C:\Users\nikol\AppData\Local\Programs\Python\Python311\Lib\site-packages\django\template\loader_tags.py", line 129, in get_parent
    return self.find_template(parent, context)
           ^^^^^^^^^^^^^^^^^^^^^^^^^^^^^^^^^^^
  File "C:\Users\nikol\AppData\Local\Programs\Python\Python311\Lib\site-packages\django\template\loader_tags.py", line 107, in find_template
    template, origin = context.template.engine.find_template(
                       ^^^^^^^^^^^^^^^^^^^^^^^^^^^^^^^^^^^^^^
  File "C:\Users\nikol\AppData\Local\Programs\Python\Python311\Lib\site-packages\django\template\engine.py", line 161, in find_template
    raise TemplateDoesNotExist(name, tried=tried)
django.template.exceptions.TemplateDoesNotExist: base.html

The above exception was the direct cause of the following exception:

Traceback (most recent call last):
  File "C:\Users\nikol\AppData\Local\Programs\Python\Python311\Lib\site-packages\django\core\handlers\exception.py", line 55, in inner
    response = get_response(request)
               ^^^^^^^^^^^^^^^^^^^^^
  File "C:\Users\nikol\AppData\Local\Programs\Python\Python311\Lib\site-packages\django\core\handlers\base.py", line 197, in _get_response
    response = wrapped_callback(request, *callback_args, **callback_kwargs)
               ^^^^^^^^^^^^^^^^^^^^^^^^^^^^^^^^^^^^^^^^^^^^^^^^^^^^^^^^^^^^
  File "C:\Users\nikol\PycharmProjects\pythonProject2\Django_dz\dz_sem3\dz_sem3app\views.py", line 19, in index
    return render(request, 'dz_sem3app/index.html', context)
           ^^^^^^^^^^^^^^^^^^^^^^^^^^^^^^^^^^^^^^^^^^^^^^^^^
  File "C:\Users\nikol\AppData\Local\Programs\Python\Python311\Lib\site-packages\django\shortcuts.py", line 24, in render
    content = loader.render_to_string(template_name, context, request, using=using)
              ^^^^^^^^^^^^^^^^^^^^^^^^^^^^^^^^^^^^^^^^^^^^^^^^^^^^^^^^^^^^^^^^^^^^^
  File "C:\Users\nikol\AppData\Local\Programs\Python\Python311\Lib\site-packages\django\template\loader.py", line 62, in render_to_string
    return template.render(context, request)
           ^^^^^^^^^^^^^^^^^^^^^^^^^^^^^^^^^
  File "C:\Users\nikol\AppData\Local\Programs\Python\Python311\Lib\site-packages\django\template\backends\django.py", line 63, in render
    reraise(exc, self.backend)
  File "C:\Users\nikol\AppData\Local\Programs\Python\Python311\Lib\site-packages\django\template\backends\django.py", line 84, in reraise
    raise new from exc
django.template.exceptions.TemplateDoesNotExist: base.html
ERROR 2023-09-29 20:51:53,636 basehttp 10856 7316 "GET /dz_sem3app/ HTTP/1.1" 500 137861
WARNING 2023-09-29 20:55:40,570 log 10856 7316 Not Found: /dz_sem3app/fake
WARNING 2023-09-29 20:55:40,571 basehttp 10856 7316 "GET /dz_sem3app/fake HTTP/1.1" 404 3408
WARNING 2023-09-29 20:56:01,774 log 10856 7316 Not Found: /dz_sem3app/fake_clients
WARNING 2023-09-29 20:56:01,775 basehttp 10856 7316 "GET /dz_sem3app/fake_clients HTTP/1.1" 404 3432
INFO 2023-09-29 20:57:25,018 basehttp 10856 7316 "GET /dz_sem3app/fake_clients/5 HTTP/1.1" 301 0
ERROR 2023-09-29 20:57:25,057 log 10856 10440 Internal Server Error: /dz_sem3app/fake_clients/5/
Traceback (most recent call last):
  File "C:\Users\nikol\AppData\Local\Programs\Python\Python311\Lib\site-packages\django\template\backends\django.py", line 61, in render
    return self.template.render(context)
           ^^^^^^^^^^^^^^^^^^^^^^^^^^^^^
  File "C:\Users\nikol\AppData\Local\Programs\Python\Python311\Lib\site-packages\django\template\base.py", line 175, in render
    return self._render(context)
           ^^^^^^^^^^^^^^^^^^^^^
  File "C:\Users\nikol\AppData\Local\Programs\Python\Python311\Lib\site-packages\django\template\base.py", line 167, in _render
    return self.nodelist.render(context)
           ^^^^^^^^^^^^^^^^^^^^^^^^^^^^^
  File "C:\Users\nikol\AppData\Local\Programs\Python\Python311\Lib\site-packages\django\template\base.py", line 1005, in render
    return SafeString("".join([node.render_annotated(context) for node in self]))
                              ^^^^^^^^^^^^^^^^^^^^^^^^^^^^^^^^^^^^^^^^^^^^^^^^^
  File "C:\Users\nikol\AppData\Local\Programs\Python\Python311\Lib\site-packages\django\template\base.py", line 1005, in <listcomp>
    return SafeString("".join([node.render_annotated(context) for node in self]))
                               ^^^^^^^^^^^^^^^^^^^^^^^^^^^^^^
  File "C:\Users\nikol\AppData\Local\Programs\Python\Python311\Lib\site-packages\django\template\base.py", line 966, in render_annotated
    return self.render(context)
           ^^^^^^^^^^^^^^^^^^^^
  File "C:\Users\nikol\AppData\Local\Programs\Python\Python311\Lib\site-packages\django\template\loader_tags.py", line 132, in render
    compiled_parent = self.get_parent(context)
                      ^^^^^^^^^^^^^^^^^^^^^^^^
  File "C:\Users\nikol\AppData\Local\Programs\Python\Python311\Lib\site-packages\django\template\loader_tags.py", line 129, in get_parent
    return self.find_template(parent, context)
           ^^^^^^^^^^^^^^^^^^^^^^^^^^^^^^^^^^^
  File "C:\Users\nikol\AppData\Local\Programs\Python\Python311\Lib\site-packages\django\template\loader_tags.py", line 107, in find_template
    template, origin = context.template.engine.find_template(
                       ^^^^^^^^^^^^^^^^^^^^^^^^^^^^^^^^^^^^^^
  File "C:\Users\nikol\AppData\Local\Programs\Python\Python311\Lib\site-packages\django\template\engine.py", line 161, in find_template
    raise TemplateDoesNotExist(name, tried=tried)
django.template.exceptions.TemplateDoesNotExist: base.html

The above exception was the direct cause of the following exception:

Traceback (most recent call last):
  File "C:\Users\nikol\AppData\Local\Programs\Python\Python311\Lib\site-packages\django\core\handlers\exception.py", line 55, in inner
    response = get_response(request)
               ^^^^^^^^^^^^^^^^^^^^^
  File "C:\Users\nikol\AppData\Local\Programs\Python\Python311\Lib\site-packages\django\core\handlers\base.py", line 197, in _get_response
    response = wrapped_callback(request, *callback_args, **callback_kwargs)
               ^^^^^^^^^^^^^^^^^^^^^^^^^^^^^^^^^^^^^^^^^^^^^^^^^^^^^^^^^^^^
  File "C:\Users\nikol\PycharmProjects\pythonProject2\Django_dz\dz_sem3\dz_sem3app\views.py", line 34, in fake_clients
    return render(request, 'dz_sem3app/fake.html', context)
           ^^^^^^^^^^^^^^^^^^^^^^^^^^^^^^^^^^^^^^^^^^^^^^^^
  File "C:\Users\nikol\AppData\Local\Programs\Python\Python311\Lib\site-packages\django\shortcuts.py", line 24, in render
    content = loader.render_to_string(template_name, context, request, using=using)
              ^^^^^^^^^^^^^^^^^^^^^^^^^^^^^^^^^^^^^^^^^^^^^^^^^^^^^^^^^^^^^^^^^^^^^
  File "C:\Users\nikol\AppData\Local\Programs\Python\Python311\Lib\site-packages\django\template\loader.py", line 62, in render_to_string
    return template.render(context, request)
           ^^^^^^^^^^^^^^^^^^^^^^^^^^^^^^^^^
  File "C:\Users\nikol\AppData\Local\Programs\Python\Python311\Lib\site-packages\django\template\backends\django.py", line 63, in render
    reraise(exc, self.backend)
  File "C:\Users\nikol\AppData\Local\Programs\Python\Python311\Lib\site-packages\django\template\backends\django.py", line 84, in reraise
    raise new from exc
django.template.exceptions.TemplateDoesNotExist: base.html
ERROR 2023-09-29 20:57:25,061 basehttp 10856 10440 "GET /dz_sem3app/fake_clients/5/ HTTP/1.1" 500 133598
WARNING 2023-09-29 20:57:39,952 log 10856 10440 Not Found: /dz_sem3app/fake_clients/
WARNING 2023-09-29 20:57:39,953 basehttp 10856 10440 "GET /dz_sem3app/fake_clients/ HTTP/1.1" 404 3435
WARNING 2023-09-29 20:57:58,479 log 10856 10440 Not Found: /dz_sem3app/fake_clients/name=mumu
WARNING 2023-09-29 20:57:58,479 basehttp 10856 10440 "GET /dz_sem3app/fake_clients/name=mumu HTTP/1.1" 404 3464
WARNING 2023-09-29 20:58:14,751 log 10856 10440 Not Found: /dz_sem3app/fake_clients/&name=mumu
WARNING 2023-09-29 20:58:14,751 basehttp 10856 10440 "GET /dz_sem3app/fake_clients/&name=mumu HTTP/1.1" 404 3479
ERROR 2023-09-29 20:58:54,040 log 10856 10440 Internal Server Error: /dz_sem3app/
Traceback (most recent call last):
  File "C:\Users\nikol\AppData\Local\Programs\Python\Python311\Lib\site-packages\django\template\backends\django.py", line 61, in render
    return self.template.render(context)
           ^^^^^^^^^^^^^^^^^^^^^^^^^^^^^
  File "C:\Users\nikol\AppData\Local\Programs\Python\Python311\Lib\site-packages\django\template\base.py", line 175, in render
    return self._render(context)
           ^^^^^^^^^^^^^^^^^^^^^
  File "C:\Users\nikol\AppData\Local\Programs\Python\Python311\Lib\site-packages\django\template\base.py", line 167, in _render
    return self.nodelist.render(context)
           ^^^^^^^^^^^^^^^^^^^^^^^^^^^^^
  File "C:\Users\nikol\AppData\Local\Programs\Python\Python311\Lib\site-packages\django\template\base.py", line 1005, in render
    return SafeString("".join([node.render_annotated(context) for node in self]))
                              ^^^^^^^^^^^^^^^^^^^^^^^^^^^^^^^^^^^^^^^^^^^^^^^^^
  File "C:\Users\nikol\AppData\Local\Programs\Python\Python311\Lib\site-packages\django\template\base.py", line 1005, in <listcomp>
    return SafeString("".join([node.render_annotated(context) for node in self]))
                               ^^^^^^^^^^^^^^^^^^^^^^^^^^^^^^
  File "C:\Users\nikol\AppData\Local\Programs\Python\Python311\Lib\site-packages\django\template\base.py", line 966, in render_annotated
    return self.render(context)
           ^^^^^^^^^^^^^^^^^^^^
  File "C:\Users\nikol\AppData\Local\Programs\Python\Python311\Lib\site-packages\django\template\loader_tags.py", line 132, in render
    compiled_parent = self.get_parent(context)
                      ^^^^^^^^^^^^^^^^^^^^^^^^
  File "C:\Users\nikol\AppData\Local\Programs\Python\Python311\Lib\site-packages\django\template\loader_tags.py", line 129, in get_parent
    return self.find_template(parent, context)
           ^^^^^^^^^^^^^^^^^^^^^^^^^^^^^^^^^^^
  File "C:\Users\nikol\AppData\Local\Programs\Python\Python311\Lib\site-packages\django\template\loader_tags.py", line 107, in find_template
    template, origin = context.template.engine.find_template(
                       ^^^^^^^^^^^^^^^^^^^^^^^^^^^^^^^^^^^^^^
  File "C:\Users\nikol\AppData\Local\Programs\Python\Python311\Lib\site-packages\django\template\engine.py", line 161, in find_template
    raise TemplateDoesNotExist(name, tried=tried)
django.template.exceptions.TemplateDoesNotExist: base.html

The above exception was the direct cause of the following exception:

Traceback (most recent call last):
  File "C:\Users\nikol\AppData\Local\Programs\Python\Python311\Lib\site-packages\django\core\handlers\exception.py", line 55, in inner
    response = get_response(request)
               ^^^^^^^^^^^^^^^^^^^^^
  File "C:\Users\nikol\AppData\Local\Programs\Python\Python311\Lib\site-packages\django\core\handlers\base.py", line 197, in _get_response
    response = wrapped_callback(request, *callback_args, **callback_kwargs)
               ^^^^^^^^^^^^^^^^^^^^^^^^^^^^^^^^^^^^^^^^^^^^^^^^^^^^^^^^^^^^
  File "C:\Users\nikol\PycharmProjects\pythonProject2\Django_dz\dz_sem3\dz_sem3app\views.py", line 19, in index
    return render(request, 'dz_sem3app/index.html', context)
           ^^^^^^^^^^^^^^^^^^^^^^^^^^^^^^^^^^^^^^^^^^^^^^^^^
  File "C:\Users\nikol\AppData\Local\Programs\Python\Python311\Lib\site-packages\django\shortcuts.py", line 24, in render
    content = loader.render_to_string(template_name, context, request, using=using)
              ^^^^^^^^^^^^^^^^^^^^^^^^^^^^^^^^^^^^^^^^^^^^^^^^^^^^^^^^^^^^^^^^^^^^^
  File "C:\Users\nikol\AppData\Local\Programs\Python\Python311\Lib\site-packages\django\template\loader.py", line 62, in render_to_string
    return template.render(context, request)
           ^^^^^^^^^^^^^^^^^^^^^^^^^^^^^^^^^
  File "C:\Users\nikol\AppData\Local\Programs\Python\Python311\Lib\site-packages\django\template\backends\django.py", line 63, in render
    reraise(exc, self.backend)
  File "C:\Users\nikol\AppData\Local\Programs\Python\Python311\Lib\site-packages\django\template\backends\django.py", line 84, in reraise
    raise new from exc
django.template.exceptions.TemplateDoesNotExist: base.html
ERROR 2023-09-29 20:58:54,044 basehttp 10856 10440 "GET /dz_sem3app/ HTTP/1.1" 500 146121
ERROR 2023-09-29 20:59:00,354 log 10856 10440 Internal Server Error: /dz_sem3app/
Traceback (most recent call last):
  File "C:\Users\nikol\AppData\Local\Programs\Python\Python311\Lib\site-packages\django\template\backends\django.py", line 61, in render
    return self.template.render(context)
           ^^^^^^^^^^^^^^^^^^^^^^^^^^^^^
  File "C:\Users\nikol\AppData\Local\Programs\Python\Python311\Lib\site-packages\django\template\base.py", line 175, in render
    return self._render(context)
           ^^^^^^^^^^^^^^^^^^^^^
  File "C:\Users\nikol\AppData\Local\Programs\Python\Python311\Lib\site-packages\django\template\base.py", line 167, in _render
    return self.nodelist.render(context)
           ^^^^^^^^^^^^^^^^^^^^^^^^^^^^^
  File "C:\Users\nikol\AppData\Local\Programs\Python\Python311\Lib\site-packages\django\template\base.py", line 1005, in render
    return SafeString("".join([node.render_annotated(context) for node in self]))
                              ^^^^^^^^^^^^^^^^^^^^^^^^^^^^^^^^^^^^^^^^^^^^^^^^^
  File "C:\Users\nikol\AppData\Local\Programs\Python\Python311\Lib\site-packages\django\template\base.py", line 1005, in <listcomp>
    return SafeString("".join([node.render_annotated(context) for node in self]))
                               ^^^^^^^^^^^^^^^^^^^^^^^^^^^^^^
  File "C:\Users\nikol\AppData\Local\Programs\Python\Python311\Lib\site-packages\django\template\base.py", line 966, in render_annotated
    return self.render(context)
           ^^^^^^^^^^^^^^^^^^^^
  File "C:\Users\nikol\AppData\Local\Programs\Python\Python311\Lib\site-packages\django\template\loader_tags.py", line 132, in render
    compiled_parent = self.get_parent(context)
                      ^^^^^^^^^^^^^^^^^^^^^^^^
  File "C:\Users\nikol\AppData\Local\Programs\Python\Python311\Lib\site-packages\django\template\loader_tags.py", line 129, in get_parent
    return self.find_template(parent, context)
           ^^^^^^^^^^^^^^^^^^^^^^^^^^^^^^^^^^^
  File "C:\Users\nikol\AppData\Local\Programs\Python\Python311\Lib\site-packages\django\template\loader_tags.py", line 107, in find_template
    template, origin = context.template.engine.find_template(
                       ^^^^^^^^^^^^^^^^^^^^^^^^^^^^^^^^^^^^^^
  File "C:\Users\nikol\AppData\Local\Programs\Python\Python311\Lib\site-packages\django\template\engine.py", line 161, in find_template
    raise TemplateDoesNotExist(name, tried=tried)
django.template.exceptions.TemplateDoesNotExist: base.html

The above exception was the direct cause of the following exception:

Traceback (most recent call last):
  File "C:\Users\nikol\AppData\Local\Programs\Python\Python311\Lib\site-packages\django\core\handlers\exception.py", line 55, in inner
    response = get_response(request)
               ^^^^^^^^^^^^^^^^^^^^^
  File "C:\Users\nikol\AppData\Local\Programs\Python\Python311\Lib\site-packages\django\core\handlers\base.py", line 197, in _get_response
    response = wrapped_callback(request, *callback_args, **callback_kwargs)
               ^^^^^^^^^^^^^^^^^^^^^^^^^^^^^^^^^^^^^^^^^^^^^^^^^^^^^^^^^^^^
  File "C:\Users\nikol\PycharmProjects\pythonProject2\Django_dz\dz_sem3\dz_sem3app\views.py", line 19, in index
    return render(request, 'dz_sem3app/index.html', context)
           ^^^^^^^^^^^^^^^^^^^^^^^^^^^^^^^^^^^^^^^^^^^^^^^^^
  File "C:\Users\nikol\AppData\Local\Programs\Python\Python311\Lib\site-packages\django\shortcuts.py", line 24, in render
    content = loader.render_to_string(template_name, context, request, using=using)
              ^^^^^^^^^^^^^^^^^^^^^^^^^^^^^^^^^^^^^^^^^^^^^^^^^^^^^^^^^^^^^^^^^^^^^
  File "C:\Users\nikol\AppData\Local\Programs\Python\Python311\Lib\site-packages\django\template\loader.py", line 62, in render_to_string
    return template.render(context, request)
           ^^^^^^^^^^^^^^^^^^^^^^^^^^^^^^^^^
  File "C:\Users\nikol\AppData\Local\Programs\Python\Python311\Lib\site-packages\django\template\backends\django.py", line 63, in render
    reraise(exc, self.backend)
  File "C:\Users\nikol\AppData\Local\Programs\Python\Python311\Lib\site-packages\django\template\backends\django.py", line 84, in reraise
    raise new from exc
django.template.exceptions.TemplateDoesNotExist: base.html
ERROR 2023-09-29 20:59:00,358 basehttp 10856 10440 "GET /dz_sem3app/ HTTP/1.1" 500 146121
INFO 2023-09-29 21:01:37,089 autoreload 14032 2192 Watching for file changes with StatReloader
ERROR 2023-09-29 21:01:40,076 log 14032 6220 Internal Server Error: /dz_sem3app/
Traceback (most recent call last):
  File "C:\Users\nikol\AppData\Local\Programs\Python\Python311\Lib\site-packages\django\template\backends\django.py", line 61, in render
    return self.template.render(context)
           ^^^^^^^^^^^^^^^^^^^^^^^^^^^^^
  File "C:\Users\nikol\AppData\Local\Programs\Python\Python311\Lib\site-packages\django\template\base.py", line 175, in render
    return self._render(context)
           ^^^^^^^^^^^^^^^^^^^^^
  File "C:\Users\nikol\AppData\Local\Programs\Python\Python311\Lib\site-packages\django\template\base.py", line 167, in _render
    return self.nodelist.render(context)
           ^^^^^^^^^^^^^^^^^^^^^^^^^^^^^
  File "C:\Users\nikol\AppData\Local\Programs\Python\Python311\Lib\site-packages\django\template\base.py", line 1005, in render
    return SafeString("".join([node.render_annotated(context) for node in self]))
                              ^^^^^^^^^^^^^^^^^^^^^^^^^^^^^^^^^^^^^^^^^^^^^^^^^
  File "C:\Users\nikol\AppData\Local\Programs\Python\Python311\Lib\site-packages\django\template\base.py", line 1005, in <listcomp>
    return SafeString("".join([node.render_annotated(context) for node in self]))
                               ^^^^^^^^^^^^^^^^^^^^^^^^^^^^^^
  File "C:\Users\nikol\AppData\Local\Programs\Python\Python311\Lib\site-packages\django\template\base.py", line 966, in render_annotated
    return self.render(context)
           ^^^^^^^^^^^^^^^^^^^^
  File "C:\Users\nikol\AppData\Local\Programs\Python\Python311\Lib\site-packages\django\template\loader_tags.py", line 132, in render
    compiled_parent = self.get_parent(context)
                      ^^^^^^^^^^^^^^^^^^^^^^^^
  File "C:\Users\nikol\AppData\Local\Programs\Python\Python311\Lib\site-packages\django\template\loader_tags.py", line 129, in get_parent
    return self.find_template(parent, context)
           ^^^^^^^^^^^^^^^^^^^^^^^^^^^^^^^^^^^
  File "C:\Users\nikol\AppData\Local\Programs\Python\Python311\Lib\site-packages\django\template\loader_tags.py", line 107, in find_template
    template, origin = context.template.engine.find_template(
                       ^^^^^^^^^^^^^^^^^^^^^^^^^^^^^^^^^^^^^^
  File "C:\Users\nikol\AppData\Local\Programs\Python\Python311\Lib\site-packages\django\template\engine.py", line 161, in find_template
    raise TemplateDoesNotExist(name, tried=tried)
django.template.exceptions.TemplateDoesNotExist: base.html

The above exception was the direct cause of the following exception:

Traceback (most recent call last):
  File "C:\Users\nikol\AppData\Local\Programs\Python\Python311\Lib\site-packages\django\core\handlers\exception.py", line 55, in inner
    response = get_response(request)
               ^^^^^^^^^^^^^^^^^^^^^
  File "C:\Users\nikol\AppData\Local\Programs\Python\Python311\Lib\site-packages\django\core\handlers\base.py", line 197, in _get_response
    response = wrapped_callback(request, *callback_args, **callback_kwargs)
               ^^^^^^^^^^^^^^^^^^^^^^^^^^^^^^^^^^^^^^^^^^^^^^^^^^^^^^^^^^^^
  File "C:\Users\nikol\PycharmProjects\pythonProject2\Django_dz\dz_sem3\dz_sem3app\views.py", line 19, in index
    return render(request, 'dz_sem3app/index.html', context)
           ^^^^^^^^^^^^^^^^^^^^^^^^^^^^^^^^^^^^^^^^^^^^^^^^^
  File "C:\Users\nikol\AppData\Local\Programs\Python\Python311\Lib\site-packages\django\shortcuts.py", line 24, in render
    content = loader.render_to_string(template_name, context, request, using=using)
              ^^^^^^^^^^^^^^^^^^^^^^^^^^^^^^^^^^^^^^^^^^^^^^^^^^^^^^^^^^^^^^^^^^^^^
  File "C:\Users\nikol\AppData\Local\Programs\Python\Python311\Lib\site-packages\django\template\loader.py", line 62, in render_to_string
    return template.render(context, request)
           ^^^^^^^^^^^^^^^^^^^^^^^^^^^^^^^^^
  File "C:\Users\nikol\AppData\Local\Programs\Python\Python311\Lib\site-packages\django\template\backends\django.py", line 63, in render
    reraise(exc, self.backend)
  File "C:\Users\nikol\AppData\Local\Programs\Python\Python311\Lib\site-packages\django\template\backends\django.py", line 84, in reraise
    raise new from exc
django.template.exceptions.TemplateDoesNotExist: base.html
ERROR 2023-09-29 21:01:40,081 basehttp 14032 6220 "GET /dz_sem3app/ HTTP/1.1" 500 146258
ERROR 2023-09-29 21:01:46,362 log 14032 6220 Internal Server Error: /dz_sem3app/
Traceback (most recent call last):
  File "C:\Users\nikol\AppData\Local\Programs\Python\Python311\Lib\site-packages\django\template\backends\django.py", line 61, in render
    return self.template.render(context)
           ^^^^^^^^^^^^^^^^^^^^^^^^^^^^^
  File "C:\Users\nikol\AppData\Local\Programs\Python\Python311\Lib\site-packages\django\template\base.py", line 175, in render
    return self._render(context)
           ^^^^^^^^^^^^^^^^^^^^^
  File "C:\Users\nikol\AppData\Local\Programs\Python\Python311\Lib\site-packages\django\template\base.py", line 167, in _render
    return self.nodelist.render(context)
           ^^^^^^^^^^^^^^^^^^^^^^^^^^^^^
  File "C:\Users\nikol\AppData\Local\Programs\Python\Python311\Lib\site-packages\django\template\base.py", line 1005, in render
    return SafeString("".join([node.render_annotated(context) for node in self]))
                              ^^^^^^^^^^^^^^^^^^^^^^^^^^^^^^^^^^^^^^^^^^^^^^^^^
  File "C:\Users\nikol\AppData\Local\Programs\Python\Python311\Lib\site-packages\django\template\base.py", line 1005, in <listcomp>
    return SafeString("".join([node.render_annotated(context) for node in self]))
                               ^^^^^^^^^^^^^^^^^^^^^^^^^^^^^^
  File "C:\Users\nikol\AppData\Local\Programs\Python\Python311\Lib\site-packages\django\template\base.py", line 966, in render_annotated
    return self.render(context)
           ^^^^^^^^^^^^^^^^^^^^
  File "C:\Users\nikol\AppData\Local\Programs\Python\Python311\Lib\site-packages\django\template\loader_tags.py", line 132, in render
    compiled_parent = self.get_parent(context)
                      ^^^^^^^^^^^^^^^^^^^^^^^^
  File "C:\Users\nikol\AppData\Local\Programs\Python\Python311\Lib\site-packages\django\template\loader_tags.py", line 129, in get_parent
    return self.find_template(parent, context)
           ^^^^^^^^^^^^^^^^^^^^^^^^^^^^^^^^^^^
  File "C:\Users\nikol\AppData\Local\Programs\Python\Python311\Lib\site-packages\django\template\loader_tags.py", line 107, in find_template
    template, origin = context.template.engine.find_template(
                       ^^^^^^^^^^^^^^^^^^^^^^^^^^^^^^^^^^^^^^
  File "C:\Users\nikol\AppData\Local\Programs\Python\Python311\Lib\site-packages\django\template\engine.py", line 161, in find_template
    raise TemplateDoesNotExist(name, tried=tried)
django.template.exceptions.TemplateDoesNotExist: base.html

The above exception was the direct cause of the following exception:

Traceback (most recent call last):
  File "C:\Users\nikol\AppData\Local\Programs\Python\Python311\Lib\site-packages\django\core\handlers\exception.py", line 55, in inner
    response = get_response(request)
               ^^^^^^^^^^^^^^^^^^^^^
  File "C:\Users\nikol\AppData\Local\Programs\Python\Python311\Lib\site-packages\django\core\handlers\base.py", line 197, in _get_response
    response = wrapped_callback(request, *callback_args, **callback_kwargs)
               ^^^^^^^^^^^^^^^^^^^^^^^^^^^^^^^^^^^^^^^^^^^^^^^^^^^^^^^^^^^^
  File "C:\Users\nikol\PycharmProjects\pythonProject2\Django_dz\dz_sem3\dz_sem3app\views.py", line 19, in index
    return render(request, 'dz_sem3app/index.html', context)
           ^^^^^^^^^^^^^^^^^^^^^^^^^^^^^^^^^^^^^^^^^^^^^^^^^
  File "C:\Users\nikol\AppData\Local\Programs\Python\Python311\Lib\site-packages\django\shortcuts.py", line 24, in render
    content = loader.render_to_string(template_name, context, request, using=using)
              ^^^^^^^^^^^^^^^^^^^^^^^^^^^^^^^^^^^^^^^^^^^^^^^^^^^^^^^^^^^^^^^^^^^^^
  File "C:\Users\nikol\AppData\Local\Programs\Python\Python311\Lib\site-packages\django\template\loader.py", line 62, in render_to_string
    return template.render(context, request)
           ^^^^^^^^^^^^^^^^^^^^^^^^^^^^^^^^^
  File "C:\Users\nikol\AppData\Local\Programs\Python\Python311\Lib\site-packages\django\template\backends\django.py", line 63, in render
    reraise(exc, self.backend)
  File "C:\Users\nikol\AppData\Local\Programs\Python\Python311\Lib\site-packages\django\template\backends\django.py", line 84, in reraise
    raise new from exc
django.template.exceptions.TemplateDoesNotExist: base.html
ERROR 2023-09-29 21:01:46,365 basehttp 14032 6220 "GET /dz_sem3app/ HTTP/1.1" 500 146121
INFO 2023-09-29 21:02:05,402 autoreload 13432 6804 Watching for file changes with StatReloader
WARNING 2023-09-29 21:02:07,226 log 13432 13912 Not Found: /
WARNING 2023-09-29 21:02:07,227 basehttp 13432 13912 "GET / HTTP/1.1" 404 2171
ERROR 2023-09-29 21:02:18,225 log 13432 13912 Internal Server Error: /dz_sem3app/
Traceback (most recent call last):
  File "C:\Users\nikol\AppData\Local\Programs\Python\Python311\Lib\site-packages\django\template\backends\django.py", line 61, in render
    return self.template.render(context)
           ^^^^^^^^^^^^^^^^^^^^^^^^^^^^^
  File "C:\Users\nikol\AppData\Local\Programs\Python\Python311\Lib\site-packages\django\template\base.py", line 175, in render
    return self._render(context)
           ^^^^^^^^^^^^^^^^^^^^^
  File "C:\Users\nikol\AppData\Local\Programs\Python\Python311\Lib\site-packages\django\template\base.py", line 167, in _render
    return self.nodelist.render(context)
           ^^^^^^^^^^^^^^^^^^^^^^^^^^^^^
  File "C:\Users\nikol\AppData\Local\Programs\Python\Python311\Lib\site-packages\django\template\base.py", line 1005, in render
    return SafeString("".join([node.render_annotated(context) for node in self]))
                              ^^^^^^^^^^^^^^^^^^^^^^^^^^^^^^^^^^^^^^^^^^^^^^^^^
  File "C:\Users\nikol\AppData\Local\Programs\Python\Python311\Lib\site-packages\django\template\base.py", line 1005, in <listcomp>
    return SafeString("".join([node.render_annotated(context) for node in self]))
                               ^^^^^^^^^^^^^^^^^^^^^^^^^^^^^^
  File "C:\Users\nikol\AppData\Local\Programs\Python\Python311\Lib\site-packages\django\template\base.py", line 966, in render_annotated
    return self.render(context)
           ^^^^^^^^^^^^^^^^^^^^
  File "C:\Users\nikol\AppData\Local\Programs\Python\Python311\Lib\site-packages\django\template\loader_tags.py", line 132, in render
    compiled_parent = self.get_parent(context)
                      ^^^^^^^^^^^^^^^^^^^^^^^^
  File "C:\Users\nikol\AppData\Local\Programs\Python\Python311\Lib\site-packages\django\template\loader_tags.py", line 129, in get_parent
    return self.find_template(parent, context)
           ^^^^^^^^^^^^^^^^^^^^^^^^^^^^^^^^^^^
  File "C:\Users\nikol\AppData\Local\Programs\Python\Python311\Lib\site-packages\django\template\loader_tags.py", line 107, in find_template
    template, origin = context.template.engine.find_template(
                       ^^^^^^^^^^^^^^^^^^^^^^^^^^^^^^^^^^^^^^
  File "C:\Users\nikol\AppData\Local\Programs\Python\Python311\Lib\site-packages\django\template\engine.py", line 161, in find_template
    raise TemplateDoesNotExist(name, tried=tried)
django.template.exceptions.TemplateDoesNotExist: base.html

The above exception was the direct cause of the following exception:

Traceback (most recent call last):
  File "C:\Users\nikol\AppData\Local\Programs\Python\Python311\Lib\site-packages\django\core\handlers\exception.py", line 55, in inner
    response = get_response(request)
               ^^^^^^^^^^^^^^^^^^^^^
  File "C:\Users\nikol\AppData\Local\Programs\Python\Python311\Lib\site-packages\django\core\handlers\base.py", line 197, in _get_response
    response = wrapped_callback(request, *callback_args, **callback_kwargs)
               ^^^^^^^^^^^^^^^^^^^^^^^^^^^^^^^^^^^^^^^^^^^^^^^^^^^^^^^^^^^^
  File "C:\Users\nikol\PycharmProjects\pythonProject2\Django_dz\dz_sem3\dz_sem3app\views.py", line 19, in index
    return render(request, 'dz_sem3app/index.html', context)
           ^^^^^^^^^^^^^^^^^^^^^^^^^^^^^^^^^^^^^^^^^^^^^^^^^
  File "C:\Users\nikol\AppData\Local\Programs\Python\Python311\Lib\site-packages\django\shortcuts.py", line 24, in render
    content = loader.render_to_string(template_name, context, request, using=using)
              ^^^^^^^^^^^^^^^^^^^^^^^^^^^^^^^^^^^^^^^^^^^^^^^^^^^^^^^^^^^^^^^^^^^^^
  File "C:\Users\nikol\AppData\Local\Programs\Python\Python311\Lib\site-packages\django\template\loader.py", line 62, in render_to_string
    return template.render(context, request)
           ^^^^^^^^^^^^^^^^^^^^^^^^^^^^^^^^^
  File "C:\Users\nikol\AppData\Local\Programs\Python\Python311\Lib\site-packages\django\template\backends\django.py", line 63, in render
    reraise(exc, self.backend)
  File "C:\Users\nikol\AppData\Local\Programs\Python\Python311\Lib\site-packages\django\template\backends\django.py", line 84, in reraise
    raise new from exc
django.template.exceptions.TemplateDoesNotExist: base.html
ERROR 2023-09-29 21:02:18,230 basehttp 13432 13912 "GET /dz_sem3app/ HTTP/1.1" 500 146395
WARNING 2023-09-29 21:02:22,799 log 13432 13912 Not Found: /dz_sem3app/index
WARNING 2023-09-29 21:02:22,799 basehttp 13432 13912 "GET /dz_sem3app/index HTTP/1.1" 404 3411
WARNING 2023-09-29 21:02:57,341 log 13432 13912 Not Found: /dz_sem3app/fake_orders
WARNING 2023-09-29 21:02:57,342 basehttp 13432 13912 "GET /dz_sem3app/fake_orders HTTP/1.1" 404 3429
WARNING 2023-09-29 21:03:50,707 log 13432 13912 Not Found: /dz_sem3app/'fake_clients/5/
WARNING 2023-09-29 21:03:50,708 basehttp 13432 13912 "GET /dz_sem3app/'fake_clients/5/ HTTP/1.1" 404 3459
INFO 2023-09-30 10:07:29,584 autoreload 3432 3452 Watching for file changes with StatReloader
WARNING 2023-09-30 10:07:31,918 log 3432 4028 Not Found: /
WARNING 2023-09-30 10:07:31,919 basehttp 3432 4028 "GET / HTTP/1.1" 404 2171
WARNING 2023-09-30 10:07:32,046 log 3432 4028 Not Found: /favicon.ico
WARNING 2023-09-30 10:07:32,047 basehttp 3432 4028 "GET /favicon.ico HTTP/1.1" 404 2222
WARNING 2023-09-30 10:07:55,478 log 3432 4028 Not Found: /
WARNING 2023-09-30 10:07:55,478 basehttp 3432 4028 "GET / HTTP/1.1" 404 2171
ERROR 2023-09-30 10:08:00,038 log 3432 4028 Internal Server Error: /dz_sem3app/
Traceback (most recent call last):
  File "C:\Users\nikol\AppData\Local\Programs\Python\Python311\Lib\site-packages\django\template\backends\django.py", line 61, in render
    return self.template.render(context)
           ^^^^^^^^^^^^^^^^^^^^^^^^^^^^^
  File "C:\Users\nikol\AppData\Local\Programs\Python\Python311\Lib\site-packages\django\template\base.py", line 175, in render
    return self._render(context)
           ^^^^^^^^^^^^^^^^^^^^^
  File "C:\Users\nikol\AppData\Local\Programs\Python\Python311\Lib\site-packages\django\template\base.py", line 167, in _render
    return self.nodelist.render(context)
           ^^^^^^^^^^^^^^^^^^^^^^^^^^^^^
  File "C:\Users\nikol\AppData\Local\Programs\Python\Python311\Lib\site-packages\django\template\base.py", line 1005, in render
    return SafeString("".join([node.render_annotated(context) for node in self]))
                              ^^^^^^^^^^^^^^^^^^^^^^^^^^^^^^^^^^^^^^^^^^^^^^^^^
  File "C:\Users\nikol\AppData\Local\Programs\Python\Python311\Lib\site-packages\django\template\base.py", line 1005, in <listcomp>
    return SafeString("".join([node.render_annotated(context) for node in self]))
                               ^^^^^^^^^^^^^^^^^^^^^^^^^^^^^^
  File "C:\Users\nikol\AppData\Local\Programs\Python\Python311\Lib\site-packages\django\template\base.py", line 966, in render_annotated
    return self.render(context)
           ^^^^^^^^^^^^^^^^^^^^
  File "C:\Users\nikol\AppData\Local\Programs\Python\Python311\Lib\site-packages\django\template\loader_tags.py", line 132, in render
    compiled_parent = self.get_parent(context)
                      ^^^^^^^^^^^^^^^^^^^^^^^^
  File "C:\Users\nikol\AppData\Local\Programs\Python\Python311\Lib\site-packages\django\template\loader_tags.py", line 129, in get_parent
    return self.find_template(parent, context)
           ^^^^^^^^^^^^^^^^^^^^^^^^^^^^^^^^^^^
  File "C:\Users\nikol\AppData\Local\Programs\Python\Python311\Lib\site-packages\django\template\loader_tags.py", line 107, in find_template
    template, origin = context.template.engine.find_template(
                       ^^^^^^^^^^^^^^^^^^^^^^^^^^^^^^^^^^^^^^
  File "C:\Users\nikol\AppData\Local\Programs\Python\Python311\Lib\site-packages\django\template\engine.py", line 161, in find_template
    raise TemplateDoesNotExist(name, tried=tried)
django.template.exceptions.TemplateDoesNotExist: dz_sem3app/base.html

The above exception was the direct cause of the following exception:

Traceback (most recent call last):
  File "C:\Users\nikol\AppData\Local\Programs\Python\Python311\Lib\site-packages\django\core\handlers\exception.py", line 55, in inner
    response = get_response(request)
               ^^^^^^^^^^^^^^^^^^^^^
  File "C:\Users\nikol\AppData\Local\Programs\Python\Python311\Lib\site-packages\django\core\handlers\base.py", line 197, in _get_response
    response = wrapped_callback(request, *callback_args, **callback_kwargs)
               ^^^^^^^^^^^^^^^^^^^^^^^^^^^^^^^^^^^^^^^^^^^^^^^^^^^^^^^^^^^^
  File "C:\Users\nikol\PycharmProjects\pythonProject2\Django_dz\dz_sem3\dz_sem3app\views.py", line 19, in index
    return render(request, 'dz_sem3app/index.html', context)
           ^^^^^^^^^^^^^^^^^^^^^^^^^^^^^^^^^^^^^^^^^^^^^^^^^
  File "C:\Users\nikol\AppData\Local\Programs\Python\Python311\Lib\site-packages\django\shortcuts.py", line 24, in render
    content = loader.render_to_string(template_name, context, request, using=using)
              ^^^^^^^^^^^^^^^^^^^^^^^^^^^^^^^^^^^^^^^^^^^^^^^^^^^^^^^^^^^^^^^^^^^^^
  File "C:\Users\nikol\AppData\Local\Programs\Python\Python311\Lib\site-packages\django\template\loader.py", line 62, in render_to_string
    return template.render(context, request)
           ^^^^^^^^^^^^^^^^^^^^^^^^^^^^^^^^^
  File "C:\Users\nikol\AppData\Local\Programs\Python\Python311\Lib\site-packages\django\template\backends\django.py", line 63, in render
    reraise(exc, self.backend)
  File "C:\Users\nikol\AppData\Local\Programs\Python\Python311\Lib\site-packages\django\template\backends\django.py", line 84, in reraise
    raise new from exc
django.template.exceptions.TemplateDoesNotExist: dz_sem3app/base.html
ERROR 2023-09-30 10:08:00,043 basehttp 3432 4028 "GET /dz_sem3app/ HTTP/1.1" 500 146454
INFO 2023-09-30 10:14:05,358 autoreload 6744 6160 Watching for file changes with StatReloader
WARNING 2023-09-30 10:14:08,334 log 6744 15052 Not Found: /dz_sem3app/index
WARNING 2023-09-30 10:14:08,335 basehttp 6744 15052 "GET /dz_sem3app/index HTTP/1.1" 404 3411
INFO 2023-09-30 10:18:50,626 autoreload 6744 6160 C:\Users\nikol\PycharmProjects\pythonProject2\Django_dz\dz_sem3\dz_sem3\settings.py changed, reloading.
INFO 2023-09-30 10:18:51,001 autoreload 9700 9684 Watching for file changes with StatReloader
INFO 2023-09-30 10:19:03,860 autoreload 8536 12908 Watching for file changes with StatReloader
WARNING 2023-09-30 10:19:07,538 log 8536 720 Not Found: /
WARNING 2023-09-30 10:19:07,538 basehttp 8536 720 "GET / HTTP/1.1" 404 2171
WARNING 2023-09-30 10:19:11,357 log 8536 720 Not Found: /
WARNING 2023-09-30 10:19:11,357 basehttp 8536 720 "GET / HTTP/1.1" 404 2171
ERROR 2023-09-30 10:19:26,973 log 8536 720 Internal Server Error: /dz_sem3app/
Traceback (most recent call last):
  File "C:\Users\nikol\AppData\Local\Programs\Python\Python311\Lib\site-packages\django\template\backends\django.py", line 61, in render
    return self.template.render(context)
           ^^^^^^^^^^^^^^^^^^^^^^^^^^^^^
  File "C:\Users\nikol\AppData\Local\Programs\Python\Python311\Lib\site-packages\django\template\base.py", line 175, in render
    return self._render(context)
           ^^^^^^^^^^^^^^^^^^^^^
  File "C:\Users\nikol\AppData\Local\Programs\Python\Python311\Lib\site-packages\django\template\base.py", line 167, in _render
    return self.nodelist.render(context)
           ^^^^^^^^^^^^^^^^^^^^^^^^^^^^^
  File "C:\Users\nikol\AppData\Local\Programs\Python\Python311\Lib\site-packages\django\template\base.py", line 1005, in render
    return SafeString("".join([node.render_annotated(context) for node in self]))
                              ^^^^^^^^^^^^^^^^^^^^^^^^^^^^^^^^^^^^^^^^^^^^^^^^^
  File "C:\Users\nikol\AppData\Local\Programs\Python\Python311\Lib\site-packages\django\template\base.py", line 1005, in <listcomp>
    return SafeString("".join([node.render_annotated(context) for node in self]))
                               ^^^^^^^^^^^^^^^^^^^^^^^^^^^^^^
  File "C:\Users\nikol\AppData\Local\Programs\Python\Python311\Lib\site-packages\django\template\base.py", line 966, in render_annotated
    return self.render(context)
           ^^^^^^^^^^^^^^^^^^^^
  File "C:\Users\nikol\AppData\Local\Programs\Python\Python311\Lib\site-packages\django\template\loader_tags.py", line 132, in render
    compiled_parent = self.get_parent(context)
                      ^^^^^^^^^^^^^^^^^^^^^^^^
  File "C:\Users\nikol\AppData\Local\Programs\Python\Python311\Lib\site-packages\django\template\loader_tags.py", line 129, in get_parent
    return self.find_template(parent, context)
           ^^^^^^^^^^^^^^^^^^^^^^^^^^^^^^^^^^^
  File "C:\Users\nikol\AppData\Local\Programs\Python\Python311\Lib\site-packages\django\template\loader_tags.py", line 107, in find_template
    template, origin = context.template.engine.find_template(
                       ^^^^^^^^^^^^^^^^^^^^^^^^^^^^^^^^^^^^^^
  File "C:\Users\nikol\AppData\Local\Programs\Python\Python311\Lib\site-packages\django\template\engine.py", line 161, in find_template
    raise TemplateDoesNotExist(name, tried=tried)
django.template.exceptions.TemplateDoesNotExist: dz_sem3app/base.html

The above exception was the direct cause of the following exception:

Traceback (most recent call last):
  File "C:\Users\nikol\AppData\Local\Programs\Python\Python311\Lib\site-packages\django\core\handlers\exception.py", line 55, in inner
    response = get_response(request)
               ^^^^^^^^^^^^^^^^^^^^^
  File "C:\Users\nikol\AppData\Local\Programs\Python\Python311\Lib\site-packages\django\core\handlers\base.py", line 197, in _get_response
    response = wrapped_callback(request, *callback_args, **callback_kwargs)
               ^^^^^^^^^^^^^^^^^^^^^^^^^^^^^^^^^^^^^^^^^^^^^^^^^^^^^^^^^^^^
  File "C:\Users\nikol\PycharmProjects\pythonProject2\Django_dz\dz_sem3\dz_sem3app\views.py", line 19, in index
    return render(request, 'dz_sem3app/index.html', context)
           ^^^^^^^^^^^^^^^^^^^^^^^^^^^^^^^^^^^^^^^^^^^^^^^^^
  File "C:\Users\nikol\AppData\Local\Programs\Python\Python311\Lib\site-packages\django\shortcuts.py", line 24, in render
    content = loader.render_to_string(template_name, context, request, using=using)
              ^^^^^^^^^^^^^^^^^^^^^^^^^^^^^^^^^^^^^^^^^^^^^^^^^^^^^^^^^^^^^^^^^^^^^
  File "C:\Users\nikol\AppData\Local\Programs\Python\Python311\Lib\site-packages\django\template\loader.py", line 62, in render_to_string
    return template.render(context, request)
           ^^^^^^^^^^^^^^^^^^^^^^^^^^^^^^^^^
  File "C:\Users\nikol\AppData\Local\Programs\Python\Python311\Lib\site-packages\django\template\backends\django.py", line 63, in render
    reraise(exc, self.backend)
  File "C:\Users\nikol\AppData\Local\Programs\Python\Python311\Lib\site-packages\django\template\backends\django.py", line 84, in reraise
    raise new from exc
django.template.exceptions.TemplateDoesNotExist: dz_sem3app/base.html
ERROR 2023-09-30 10:19:26,977 basehttp 8536 720 "GET /dz_sem3app/ HTTP/1.1" 500 147232
INFO 2023-09-30 10:22:48,288 basehttp 8536 720 "GET /dz_sem3app/ HTTP/1.1" 200 4620
INFO 2023-09-30 10:22:52,057 basehttp 8536 720 "GET /dz_sem3app/show_client_orders/1/ HTTP/1.1" 200 340
INFO 2023-09-30 10:22:56,349 basehttp 8536 720 "GET /dz_sem3app/show_client_orders/2/ HTTP/1.1" 200 340
INFO 2023-09-30 10:23:00,204 basehttp 8536 720 "GET /dz_sem3app/show_client_orders/5/ HTTP/1.1" 200 340
INFO 2023-09-30 10:23:05,783 basehttp 8536 720 "GET /dz_sem3app/list_goods_period_of_time/7/4 HTTP/1.1" 200 501
WARNING 2023-09-30 10:23:16,291 log 8536 720 Not Found: /dz_sem3app/index
WARNING 2023-09-30 10:23:16,291 basehttp 8536 720 "GET /dz_sem3app/index HTTP/1.1" 404 3411
WARNING 2023-09-30 10:23:22,274 log 8536 720 Not Found: /dz_sem3app/index/5
WARNING 2023-09-30 10:23:22,274 basehttp 8536 720 "GET /dz_sem3app/index/5 HTTP/1.1" 404 3417
WARNING 2023-09-30 10:23:44,306 log 8536 720 Not Found: /dz_sem3app/fake_client/5
WARNING 2023-09-30 10:23:44,307 basehttp 8536 720 "GET /dz_sem3app/fake_client/5 HTTP/1.1" 404 3435
WARNING 2023-09-30 10:24:30,586 log 8536 720 Not Found: /dz_sem3app/fake_clients
WARNING 2023-09-30 10:24:30,587 basehttp 8536 720 "GET /dz_sem3app/fake_clients HTTP/1.1" 404 3432
INFO 2023-09-30 10:24:40,007 basehttp 8536 720 "GET /dz_sem3app/fake_clients/5/ HTTP/1.1" 200 281
INFO 2023-09-30 10:25:00,931 basehttp 8536 720 "GET /dz_sem3app/fake_products/3 HTTP/1.1" 301 0
INFO 2023-09-30 10:25:00,944 basehttp 8536 11016 "GET /dz_sem3app/fake_products/3/ HTTP/1.1" 200 282
WARNING 2023-09-30 10:25:22,386 log 8536 11016 Not Found: /dz_sem3app/show_client_orders_test/5
WARNING 2023-09-30 10:25:22,387 basehttp 8536 11016 "GET /dz_sem3app/show_client_orders_test/5 HTTP/1.1" 404 3471
WARNING 2023-09-30 10:25:47,235 log 8536 11016 Not Found: /dz_sem3app/list_goods_period_of_time/25
WARNING 2023-09-30 10:25:47,235 basehttp 8536 11016 "GET /dz_sem3app/list_goods_period_of_time/25 HTTP/1.1" 404 3480
INFO 2023-09-30 10:25:53,297 basehttp 8536 11016 "GET /dz_sem3app/list_goods_period_of_time/25/2 HTTP/1.1" 200 502
WARNING 2023-09-30 10:27:08,189 log 8536 11016 Not Found: /dz_sem3app/fake_products
WARNING 2023-09-30 10:27:08,190 basehttp 8536 11016 "GET /dz_sem3app/fake_products HTTP/1.1" 404 3435
INFO 2023-09-30 10:27:12,403 basehttp 8536 11016 "GET /dz_sem3app/fake_products/3/ HTTP/1.1" 200 282
WARNING 2023-09-30 10:29:31,958 log 8536 11016 Not Found: /dz_sem3app/list_goods_period_of_time
WARNING 2023-09-30 10:29:31,958 basehttp 8536 11016 "GET /dz_sem3app/list_goods_period_of_time HTTP/1.1" 404 3471
WARNING 2023-09-30 10:29:41,370 log 8536 11016 Not Found: /dz_sem3app/list_goods_period_of_time/25
WARNING 2023-09-30 10:29:41,371 basehttp 8536 11016 "GET /dz_sem3app/list_goods_period_of_time/25 HTTP/1.1" 404 3480
INFO 2023-09-30 10:29:52,449 basehttp 8536 11016 "GET /dz_sem3app/list_goods_period_of_time/25/5 HTTP/1.1" 200 502
INFO 2023-09-30 10:29:59,921 basehttp 8536 11016 "GET /dz_sem3app/list_goods_period_of_time/25/4 HTTP/1.1" 200 502
WARNING 2023-09-30 10:30:18,428 log 8536 11016 Not Found: /dz_sem3app/show_client_orders
WARNING 2023-09-30 10:30:18,428 basehttp 8536 11016 "GET /dz_sem3app/show_client_orders HTTP/1.1" 404 3450
INFO 2023-09-30 10:30:31,634 basehttp 8536 11016 "GET /dz_sem3app/show_client_orders/1 HTTP/1.1" 301 0
INFO 2023-09-30 10:30:31,638 basehttp 8536 5696 "GET /dz_sem3app/show_client_orders/1/ HTTP/1.1" 200 340
ERROR 2023-09-30 10:31:11,968 log 8536 5696 Internal Server Error: /dz_sem3app/fake_products/3/
Traceback (most recent call last):
  File "C:\Users\nikol\AppData\Local\Programs\Python\Python311\Lib\site-packages\django\db\utils.py", line 98, in inner
    return func(*args, **kwargs)
           ^^^^^^^^^^^^^^^^^^^^^
sqlite3.OperationalError: database is locked

The above exception was the direct cause of the following exception:

Traceback (most recent call last):
  File "C:\Users\nikol\AppData\Local\Programs\Python\Python311\Lib\site-packages\django\core\handlers\exception.py", line 55, in inner
    response = get_response(request)
               ^^^^^^^^^^^^^^^^^^^^^
  File "C:\Users\nikol\AppData\Local\Programs\Python\Python311\Lib\site-packages\django\core\handlers\base.py", line 197, in _get_response
    response = wrapped_callback(request, *callback_args, **callback_kwargs)
               ^^^^^^^^^^^^^^^^^^^^^^^^^^^^^^^^^^^^^^^^^^^^^^^^^^^^^^^^^^^^
  File "C:\Users\nikol\PycharmProjects\pythonProject2\Django_dz\dz_sem3\dz_sem3app\views.py", line 45, in fake_products
    product.save()
  File "C:\Users\nikol\AppData\Local\Programs\Python\Python311\Lib\site-packages\django\db\models\base.py", line 814, in save
    self.save_base(
  File "C:\Users\nikol\AppData\Local\Programs\Python\Python311\Lib\site-packages\django\db\models\base.py", line 877, in save_base
    updated = self._save_table(
              ^^^^^^^^^^^^^^^^^
  File "C:\Users\nikol\AppData\Local\Programs\Python\Python311\Lib\site-packages\django\db\models\base.py", line 1020, in _save_table
    results = self._do_insert(
              ^^^^^^^^^^^^^^^^
  File "C:\Users\nikol\AppData\Local\Programs\Python\Python311\Lib\site-packages\django\db\models\base.py", line 1061, in _do_insert
    return manager._insert(
           ^^^^^^^^^^^^^^^^
  File "C:\Users\nikol\AppData\Local\Programs\Python\Python311\Lib\site-packages\django\db\models\manager.py", line 87, in manager_method
    return getattr(self.get_queryset(), name)(*args, **kwargs)
           ^^^^^^^^^^^^^^^^^^^^^^^^^^^^^^^^^^^^^^^^^^^^^^^^^^^
  File "C:\Users\nikol\AppData\Local\Programs\Python\Python311\Lib\site-packages\django\db\models\query.py", line 1805, in _insert
    return query.get_compiler(using=using).execute_sql(returning_fields)
           ^^^^^^^^^^^^^^^^^^^^^^^^^^^^^^^^^^^^^^^^^^^^^^^^^^^^^^^^^^^^^
  File "C:\Users\nikol\AppData\Local\Programs\Python\Python311\Lib\site-packages\django\db\models\sql\compiler.py", line 1833, in execute_sql
    self.connection.ops.fetch_returned_insert_columns(
  File "C:\Users\nikol\AppData\Local\Programs\Python\Python311\Lib\site-packages\django\db\backends\base\operations.py", line 213, in fetch_returned_insert_columns
    return cursor.fetchone()
           ^^^^^^^^^^^^^^^^^
  File "C:\Users\nikol\AppData\Local\Programs\Python\Python311\Lib\site-packages\django\db\utils.py", line 97, in inner
    with self:
  File "C:\Users\nikol\AppData\Local\Programs\Python\Python311\Lib\site-packages\django\db\utils.py", line 91, in __exit__
    raise dj_exc_value.with_traceback(traceback) from exc_value
  File "C:\Users\nikol\AppData\Local\Programs\Python\Python311\Lib\site-packages\django\db\utils.py", line 98, in inner
    return func(*args, **kwargs)
           ^^^^^^^^^^^^^^^^^^^^^
django.db.utils.OperationalError: database is locked
ERROR 2023-09-30 10:31:11,972 basehttp 8536 5696 "GET /dz_sem3app/fake_products/3/ HTTP/1.1" 500 127784
WARNING 2023-09-30 10:31:18,129 log 8536 5696 Not Found: /dz_sem3app/fake_products/3/3
WARNING 2023-09-30 10:31:18,130 basehttp 8536 5696 "GET /dz_sem3app/fake_products/3/3 HTTP/1.1" 404 3447
